<?xml version="1.0" encoding="utf-8"?>
<!-- This URDF was automatically created by SolidWorks to URDF Exporter! Originally created by Stephen Brawner (brawner@gmail.com) 
     Commit Version: 1.6.0-1-g15f4949  Build Version: 1.6.7594.29634
     For more information, please see http://wiki.ros.org/sw_urdf_exporter -->
<robot name="ackermann_robot">
  
  <gazebo>
    <plugin name="gazebo_ros_control" filename="libgazebo_ros_control.so">
      <!--robotNamespace>/ackermann_model</robotNamespace-->
    </plugin>
  </gazebo>
  <!--Comentar>
  <link name="world">
    <visual>
      <geometry>
        <box size="0.01 0.01 0.01"/>
      </geometry>
      <material name="chassis_mat"/>
    </visual>
  </link>
  <gazebo reference="base_link">
    <material>Gazebo/Black</material>
  </gazebo>
  <joint name="world_to_base_link" type="fixed">
    <parent link="world"/>
    <child link="base_link"/>
  </joint-->

   <link name="base_link">
    <inertial>
      <origin
        xyz="8.858E-05 -1.9843E-06 0.020487"
        rpy="0 0 0" />
      <mass
        value="0.3999" />
      <inertia
        ixx="0.00065026"
        ixy="-8.0029E-08"
        ixz="-1.4859E-21"
        iyy="0.0027365"
        iyz="-1.4915E-21"
        izz="0.0033851" />
    </inertial>
    <visual>
      <origin
        xyz="0 0 0"
        rpy="0 0 0" />
      <geometry>
        <mesh
          filename="package://ackermann_robot_description/meshes/base_link.STL" />
      </geometry>
      <material
        name="">
        <color
          rgba="0.79216 0.81961 0.93333 1" />
      </material>
    </visual>
    <collision>
      <origin
        xyz="0 0 0"
        rpy="0 0 0" />
      <geometry>
        <mesh
          filename="package://ackermann_robot_description/meshes/base_link.STL" />
      </geometry>
    </collision>
  </link>
  <link name="right_front_axle_carrier">
    <inertial>
      <origin
        xyz="0.0014472 -0.0045945 1.0684E-07"
        rpy="0 0 0" />
      <mass
        value="0.012162" />
      <inertia
        ixx="1.1801E-06"
        ixy="-7.7079E-08"
        ixz="-2.8872E-13"
        iyy="8.0582E-07"
        iyz="6.3391E-14"
        izz="1.3986E-06" />
    </inertial>
    <visual>
      <origin
        xyz="0 0 0"
        rpy="0 0 0" />
      <geometry>
        <mesh
          filename="package://ackermann_robot_description/meshes/right_front_axle_carrier.STL" />
      </geometry>
      <material
        name="">
        <color
          rgba="0.79216 0.81961 0.93333 1" />
      </material>
    </visual>
    <collision>
      <origin
        xyz="0 0 0"
        rpy="0 0 0" />
      <geometry>
        <mesh
          filename="package://ackermann_robot_description/meshes/right_front_axle_carrier.STL" />
      </geometry>
    </collision>
  </link>
  <joint name="right_steering_joint" type="revolute">
    <origin xyz="0.11246 -0.055004 0.020259" rpy="0 0 -0.10142" />
    <parent link="base_link" />
    <child
      link="right_front_axle_carrier" />
    <axis
      xyz="0 0 1" />
    <limit
      lower="-0.4"
      upper="0.5"
      effort="0.5"
      velocity="1" />
  </joint>
  <transmission name="right_steering_trans">
    <type>transmission_interface/SimpleTransmission</type>
    <joint name="right_steering_joint">
      <hardwareInterface>hardware_interface/EffortJointInterface</hardwareInterface>
    </joint>
    <actuator name="right_steering_act">
      <hardwareInterface>hardware_interface/EffortJointInterface</hardwareInterface>
      <mechanicalReduction>1</mechanicalReduction>
    </actuator>
  </transmission>

  <link name="right_front_wheel">
    <inertial>
      <origin
        xyz="0 -0.0032519 -9.2198E-17"
        rpy="0 0 0" />
      <mass
        value="0.04847" />
      <inertia
        ixx="2.1185E-05"
        ixy="1.3976E-20"
        ixz="-3.0394E-21"
        iyy="3.7185E-05"
        iyz="-3.4283E-20"
        izz="2.1185E-05" />
    </inertial>
    <visual>
      <origin
        xyz="0 0 0"
        rpy="0 0 0" />
      <geometry>
        <mesh
          filename="package://ackermann_robot_description/meshes/right_front_wheel.STL" />
      </geometry>
      <material
        name="">
        <color
          rgba="0.79216 0.81961 0.93333 1" />
      </material>
    </visual>
    <collision>
      <origin
        xyz="0 0 0"
        rpy="0 0 0" />
      <geometry>
        <mesh
          filename="package://ackermann_robot_description/meshes/right_front_wheel.STL" />
      </geometry>
    </collision>
  </link>
  <joint name="right_front_axle" type="continuous">
    <origin xyz="0 -0.0355 0" rpy="0 0 0" />
    <parent link="right_front_axle_carrier" />
    <child link="right_front_wheel" />
    <axis xyz="0 1 0" />
    <limit effort="5" velocity="15"/>
  </joint>
  <transmission name="right_front_axle_trans">
    <type>transmission_interface/SimpleTransmission</type>
    <joint name="right_front_axle">
      <hardwareInterface>hardware_interface/EffortJointInterface</hardwareInterface>
    </joint>
    <actuator name="right_front_axle_act">
      <hardwareInterface>hardware_interface/EffortJointInterface</hardwareInterface>
      <mechanicalReduction>1</mechanicalReduction>
    </actuator>
  </transmission>

  <link name="left_front_axle_carrier">
    <inertial>
      <origin
        xyz="0.0014472 0.0045945 -1.0684E-07"
        rpy="0 0 0" />
      <mass
        value="0.012162" />
      <inertia
        ixx="1.1801E-06"
        ixy="7.7079E-08"
        ixz="2.8872E-13"
        iyy="8.0582E-07"
        iyz="6.3391E-14"
        izz="1.3986E-06" />
    </inertial>
    <visual>
      <origin
        xyz="0 0 0"
        rpy="0 0 0" />
      <geometry>
        <mesh
          filename="package://ackermann_robot_description/meshes/left_front_axle_carrier.STL" />
      </geometry>
      <material
        name="">
        <color
          rgba="0.79216 0.81961 0.93333 1" />
      </material>
    </visual>
    <collision>
      <origin
        xyz="0 0 0"
        rpy="0 0 0" />
      <geometry>
        <mesh
          filename="package://ackermann_robot_description/meshes/left_front_axle_carrier.STL" />
      </geometry>
    </collision>
  </link>
  <joint name="left_steering_joint" type="revolute">
    <origin
      xyz="0.11246 0.054996 0.020303"
      rpy="0 0 0.049922" />
    <parent
      link="base_link" />
    <child
      link="left_front_axle_carrier" />
    <axis
      xyz="0 0 1" />
    <limit
      lower="-0.4"
      upper="0.5"
      effort="0.5"
      velocity="1" />
  </joint>
  <transmission name="left_steering_trans">
    <type>transmission_interface/SimpleTransmission</type>
    <joint name="left_steering_joint">
      <hardwareInterface>hardware_interface/EffortJointInterface</hardwareInterface>
    </joint>
    <actuator name="left_steering_act">
      <hardwareInterface>hardware_interface/EffortJointInterface</hardwareInterface>
      <mechanicalReduction>1</mechanicalReduction>
    </actuator>
  </transmission>
  
  <link name="left_front_wheel">
    <inertial>
      <origin
        xyz="2.7756E-17 0.0032519 9.3404E-17"
        rpy="0 0 0" />
      <mass
        value="0.04847" />
      <inertia
        ixx="2.1185E-05"
        ixy="-1.6517E-20"
        ixz="4.112E-21"
        iyy="3.7185E-05"
        iyz="-3.4164E-20"
        izz="2.1185E-05" />
    </inertial>
    <visual>
      <origin
        xyz="0 0 0"
        rpy="0 0 0" />
      <geometry>
        <mesh
          filename="package://ackermann_robot_description/meshes/left_front_wheel.STL" />
      </geometry>
      <material
        name="">
        <color
          rgba="0.79216 0.81961 0.93333 1" />
      </material>
    </visual>
    <collision>
      <origin
        xyz="0 0 0"
        rpy="0 0 0" />
      <geometry>
        <mesh
          filename="package://ackermann_robot_description/meshes/left_front_wheel.STL" />
      </geometry>
    </collision>
  </link>
  <joint name="left_front_axle" type="continuous">
    <origin xyz="0 0.0355 0" rpy="0 0 0" />
    <parent link="left_front_axle_carrier" />
    <child link="left_front_wheel" />
    <axis xyz="0 1 0" />
    <limit effort="5" velocity="15"/>
  </joint>
  <transmission name="left_front_axle_trans">
    <type>transmission_interface/SimpleTransmission</type>
    <joint name="left_front_axle">
      <hardwareInterface>hardware_interface/EffortJointInterface</hardwareInterface>
    </joint>
    <actuator name="left_front_axle_act">
      <hardwareInterface>hardware_interface/EffortJointInterface</hardwareInterface>
      <mechanicalReduction>1</mechanicalReduction>
    </actuator>
  </transmission>

  <link name="right_rear_axle_carrier">
    <inertial>
      <origin
        xyz="0 0.02273 0.0026785"
        rpy="0 0 0" />
      <mass
        value="0.032121" />
      <inertia
        ixx="8.4438E-06"
        ixy="9.7303E-22"
        ixz="-1.6257E-22"
        iyy="2.811E-06"
        iyz="-4.3914E-07"
        izz="8.6197E-06" />
    </inertial>
    <visual>
      <origin
        xyz="0 0 0"
        rpy="0 0 0" />
      <geometry>
        <mesh
          filename="package://ackermann_robot_description/meshes/right_rear_axle_carrier.STL" />
      </geometry>
      <material
        name="">
        <color
          rgba="0.79216 0.81961 0.93333 1" />
      </material>
    </visual>
    <collision>
      <origin
        xyz="0 0 0"
        rpy="0 0 0" />
      <geometry>
        <mesh
          filename="package://ackermann_robot_description/meshes/right_rear_axle_carrier.STL" />
      </geometry>
    </collision>
  </link>
  <joint name="right_rear_fixed" type="fixed">
    <origin
      xyz="-0.087539 -0.074004 0.019"
      rpy="0 0 0" />
    <parent
      link="base_link" />
    <child
      link="right_rear_axle_carrier" />
    <axis
      xyz="0 0 0" />
  </joint>
  <link name="right_rear_wheel">
    <inertial>
      <origin
        xyz="1.3878E-17 -0.0032519 -1.0387E-16"
        rpy="0 0 0" />
      <mass
        value="0.04847" />
      <inertia
        ixx="2.1185E-05"
        ixy="1.7085E-20"
        ixz="-4.3879E-21"
        iyy="3.7185E-05"
        iyz="-3.5493E-20"
        izz="2.1185E-05" />
    </inertial>
    <visual>
      <origin
        xyz="0 0 0"
        rpy="0 0 0" />
      <geometry>
        <mesh
          filename="package://ackermann_robot_description/meshes/right_rear_wheel.STL" />
      </geometry>
      <material
        name="">
        <color
          rgba="0.79216 0.81961 0.93333 1" />
      </material>
    </visual>
    <collision>
      <origin
        xyz="0 0 0"
        rpy="0 0 0" />
      <geometry>
        <mesh
          filename="package://ackermann_robot_description/meshes/right_rear_wheel.STL" />
      </geometry>
    </collision>
  </link>
  <joint name="right_rear_axle" type="continuous">
    <origin xyz="0 -0.0165 0" rpy="0 0 0" />
    <parent link="right_rear_axle_carrier" />
    <child link="right_rear_wheel" />
    <axis xyz="0 1 0" />
    <limit effort="5" velocity="15"/>
  </joint>
  <transmission name="right_rear_axle_trans">
    <type>transmission_interface/SimpleTransmission</type>
    <joint name="right_rear_axle">
      <hardwareInterface>hardware_interface/EffortJointInterface</hardwareInterface>
    </joint>
    <actuator name="right_rear_axle_act">
      <hardwareInterface>hardware_interface/EffortJointInterface</hardwareInterface>
      <mechanicalReduction>1</mechanicalReduction>
    </actuator>
  </transmission>

  <link name="left_rear_axle_carrier">
    <inertial>
      <origin
        xyz="2.7756E-17 -0.02273 0.0026785"
        rpy="0 0 0" />
      <mass
        value="0.032121" />
      <inertia
        ixx="8.4438E-06"
        ixy="7.4384E-22"
        ixz="2.7615E-22"
        iyy="2.811E-06"
        iyz="4.3914E-07"
        izz="8.6197E-06" />
    </inertial>
    <visual>
      <origin
        xyz="0 0 0"
        rpy="0 0 0" />
      <geometry>
        <mesh
          filename="package://ackermann_robot_description/meshes/left_rear_axle_carrier.STL" />
      </geometry>
      <material
        name="">
        <color
          rgba="0.79216 0.81961 0.93333 1" />
      </material>
    </visual>
    <collision>
      <origin
        xyz="0 0 0"
        rpy="0 0 0" />
      <geometry>
        <mesh
          filename="package://ackermann_robot_description/meshes/left_rear_axle_carrier.STL" />
      </geometry>
    </collision>
  </link>
  <joint name="left_rear_fixed" type="fixed">
    <origin
      xyz="-0.087539 0.073996 0.019"
      rpy="0 0 0" />
    <parent
      link="base_link" />
    <child
      link="left_rear_axle_carrier" />
    <axis
      xyz="0 0 0" />
  </joint>
  <link name="left_rear_wheel">
    <inertial>
      <origin
        xyz="5.5511E-17 0.0032519 -8.305E-17"
        rpy="0 0 0" />
      <mass
        value="0.04847" />
      <inertia
        ixx="2.1185E-05"
        ixy="-1.6287E-20"
        ixz="5.7903E-21"
        iyy="3.7185E-05"
        iyz="-3.7913E-20"
        izz="2.1185E-05" />
    </inertial>
    <visual>
      <origin
        xyz="0 0 0"
        rpy="0 0 0" />
      <geometry>
        <mesh
          filename="package://ackermann_robot_description/meshes/left_rear_wheel.STL" />
      </geometry>
      <material
        name="">
        <color
          rgba="0.79216 0.81961 0.93333 1" />
      </material>
    </visual>
    <collision>
      <origin
        xyz="0 0 0"
        rpy="0 0 0" />
      <geometry>
        <mesh
          filename="package://ackermann_robot_description/meshes/left_rear_wheel.STL" />
      </geometry>
    </collision>
  </link>
  <joint name="left_rear_axle" type="continuous">
    <origin xyz="0 0.0165 0" rpy="0 0 0" />
    <parent link="left_rear_axle_carrier" />
    <child link="left_rear_wheel" />
    <axis xyz="0 1 0" />
    <limit effort="5" velocity="15"/>
  </joint>
  <transmission name="left_rear_axle_trans">
    <type>transmission_interface/SimpleTransmission</type>
    <joint name="left_rear_axle">
      <hardwareInterface>hardware_interface/EffortJointInterface</hardwareInterface>
    </joint>
    <actuator name="left_rear_axle_act">
      <hardwareInterface>hardware_interface/EffortJointInterface</hardwareInterface>
      <mechanicalReduction>1</mechanicalReduction>
    </actuator>
  </transmission>
</robot>